<?xml version="1.0" encoding="utf-8"?>
<!-- This URDF was automatically created by SolidWorks to URDF Exporter! Originally created by Stephen Brawner (brawner@gmail.com) 
     Commit Version: 1.6.0-4-g7f85cfe  Build Version: 1.6.7995.38578
     For more information, please see http://wiki.ros.org/sw_urdf_exporter -->
<robot
  name="urdf_template_4">
  <link
    name="base_link">
    <!--inertial>
      <origin
        xyz="0.0635 0.012762 0.074951"
        rpy="0 0 0" />
      <mass
        value="0.21545" />
      <inertia
        ixx="0.00043021"
        ixy="-3.45E-13"
        ixz="-5.421E-20"
        iyy="0.00074493"
        iyz="-1.1884E-20"
        izz="0.00031616" />
    </inertia-->
    <visual>
      <origin
        xyz="0 0.125 0"
        rpy="1.570796 0 0" />
      <geometry>
        <mesh
          filename="package://urdf_template_4/meshes/base_link.STL" />
      </geometry>
      <material
        name="">
        <color
          rgba="0.79216 0.81961 0.93333 1" />
      </material>
    </visual>
    <collision>
      <origin
        xyz="0 0.125 0"
        rpy="1.570796 0 0" />
      <geometry>
        <mesh
          filename="package://urdf_template_4/meshes/base_link.STL" />
      </geometry>
    </collision>
  </link>
  <link
    name="link_1">
    <!--inertial>
      <origin
        xyz="-0.00022366 -0.0033649 -0.017961"
        rpy="0 0 0" />
      <mass
        value="0.12444" />
      <inertia
        ixx="6.1915E-05"
        ixy="-8.54E-07"
        ixz="8.1967E-07"
        iyy="4.9473E-05"
        iyz="1.1904E-05"
        izz="5.3215E-05" />
    </inertia-->
    <visual>
      <origin
        xyz="0 0 0"
        rpy="0 0 0" />
      <geometry>
        <mesh
          filename="package://urdf_template_4/meshes/link_1.STL" />
      </geometry>
      <material
        name="">
        <color
          rgba="0.79216 0.81961 0.93333 1" />
      </material>
    </visual>
    <collision>
      <origin
        xyz="0 0 0"
        rpy="0 0 0" />
      <geometry>
        <mesh
          filename="package://urdf_template_4/meshes/link_1.STL" />
      </geometry>
    </collision>
  </link>
  <joint
    name="Joint_1"
    type="revolute">
    <origin
      xyz="0.0650066711333143 0.0651925420406113 0.063822562470066"
      rpy="0 0 -3.14159265249356" />
    <parent
      link="base_link" />
    <child
      link="link_1" />
    <axis
      xyz="0 0 1" />
    <limit
      lower="-2.618"
      upper="2.618"
      effort="0"
      velocity="0" />
  </joint>
  <link
    name="link_2">
    <!--inertial>
      <origin
        xyz="-0.0001791 0.022541 0.16524"
        rpy="0 0 0" />
      <mass
        value="0.097799" />
      <inertia
        ixx="0.0012357"
        ixy="-3.6545E-06"
        ixz="-1.367E-05"
        iyy="0.0011829"
        iyz="-0.00019852"
        izz="5.3488E-05" />
    </inertia-->
    <visual>
      <origin
        xyz="0 0 0"
        rpy="0 0 0" />
      <geometry>
        <mesh
          filename="package://urdf_template_4/meshes/link_2.STL" />
      </geometry>
      <material
        name="">
        <color
          rgba="0.79216 0.81961 0.93333 1" />
      </material>
    </visual>
    <collision>
      <origin
        xyz="0 0 0"
        rpy="0 0 0" />
      <geometry>
        <mesh
          filename="package://urdf_template_4/meshes/link_2.STL" />
      </geometry>
    </collision>
  </link>
  <joint
    name="Joint_2"
    type="revolute">
    <origin
      xyz="0 0 0.028575"
      rpy="0 0 0" />
    <parent
      link="link_1" />
    <child
      link="link_2" />
    <axis
      xyz="-0.997637620258692 0.0686962782439793 0" />
    <limit
      lower="1.1284"
      upper="0.45"
      effort="0"
      velocity="0" />
  </joint>
  <link
    name="link_3">
    <!--inertial>
      <origin
        xyz="0.011884 0.13988 -0.051253"
        rpy="0 0 0" />
      <mass
        value="0.14198" />
      <inertia
        ixx="0.001247"
        ixy="-7.363E-05"
        ixz="2.4228E-05"
        iyy="0.00018276"
        iyz="0.00035184"
        izz="0.0010837" />
    </inertia-->
    <visual>
      <origin
        xyz="0 0 0"
        rpy="0 0 0" />
      <geometry>
        <mesh
          filename="package://urdf_template_4/meshes/link_3.STL" />
      </geometry>
      <material
        name="">
        <color
          rgba="0.79216 0.81961 0.93333 1" />
      </material>
    </visual>
    <collision>
      <origin
        xyz="0 0 0"
        rpy="0 0 0" />
      <geometry>
        <mesh
          filename="package://urdf_template_4/meshes/link_3.STL" />
      </geometry>
    </collision>
  </link>
  <joint
    name="Joint_3"
    type="revolute">
    <origin
      xyz="0.00352905769600124 0.0745463768419771 0.350158363506979"
      rpy="0 0 0" />
    <parent
      link="link_2" />
    <child
      link="link_3" />
    <axis
      xyz="0.997637620258692 -0.0686962782439819 0" />
    <limit
      lower="0"
      upper="0.7854"
      effort="0"
      velocity="0" />
  </joint>
  <link
    name="link_4">
    <!--inertial>
      <origin
        xyz="-0.0037679 0.11386 -0.10931"
        rpy="0 0 0" />
      <mass
        value="0.38011" />
      <inertia
        ixx="0.0011069"
        ixy="3.747E-05"
        ixz="-3.567E-05"
        iyy="0.00063756"
        iyz="0.00045467"
        izz="0.00067749" />
    </inertia-->
    <visual>
      <origin
        xyz="0 0 0"
        rpy="0 0 0" />
      <geometry>
        <mesh
          filename="package://urdf_template_4/meshes/link_4.STL" />
      </geometry>
      <material
        name="">
        <color
          rgba="0.79216 0.81961 0.93333 1" />
      </material>
    </visual>
    <collision>
      <origin
        xyz="0 0 0"
        rpy="0 0 0" />
      <geometry>
        <mesh
          filename="package://urdf_template_4/meshes/link_4.STL" />
      </geometry>
    </collision>
  </link>
  <joint
    name="Joint_4"
    type="revolute">
    <origin
      xyz="0.02567074846148 0.261630460097419 -0.0987385223146501"
      rpy="0 0 0" />
    <parent
      link="link_3" />
    <child
      link="link_4" />
    <axis
      xyz="0.997637620258692 -0.0686962782439826 0" />
    <limit
      lower="-1.8"
      upper="2.793"
      effort="0"
      velocity="0" />
  </joint>
  <link
    name="link_5">
    <!--inertial>
      <origin
        xyz="-0.0012782 0.081139 -0.077506"
        rpy="0 0 0" />
      <mass
        value="0.50218" />
      <inertia
        ixx="0.00041657"
        ixy="-3.9613E-06"
        ixz="-4.2289E-06"
        iyy="0.00028848"
        iyz="5.399E-06"
        izz="0.00029155" />
    </inertia-->
    <visual>
      <origin
        xyz="0 0 0"
        rpy="0 0 0" />
      <geometry>
        <mesh
          filename="package://urdf_template_4/meshes/link_5.STL" />
      </geometry>
      <material
        name="">
        <color
          rgba="0.79216 0.81961 0.93333 1" />
      </material>
    </visual>
    <collision>
      <origin
        xyz="0 0 0"
        rpy="0 0 0" />
      <geometry>
        <mesh
          filename="package://urdf_template_4/meshes/link_5.STL" />
      </geometry>
    </collision>
  </link>
  <joint
    name="Joint_5"
    type="continuous">
    <origin
      xyz="0.0078847 0.21145 -0.20399"
      rpy="0 0 0" />
    <parent
      link="link_4" />
    <child
      link="link_5" />
    <axis
      xyz="-0.0010653 0.72061 -0.69334" />
  </joint>
</robot>
